We are using NVIDIA TITAN V
======================================================================













This is the 0 run
==================================================
rm: cannot remove './saved/models/new_model/*': No such file or directory












Warning: logging configuration file is not found in logger/logger_config.json.
Dataset len:  726
INFO:train:Model(
  (fc1): Linear(in_features=2688, out_features=256, bias=True)
  (fc2): Linear(in_features=256, out_features=48, bias=True)
  (conv1): Conv2d(1, 8, kernel_size=(2, 2), stride=(2, 2), padding=(1, 1))
  (conv2): Conv2d(8, 16, kernel_size=(3, 3), stride=(2, 2), padding=(1, 1))
  (global1): AvgPool2d(kernel_size=3, stride=1, padding=1)
  (avgpool): AdaptiveAvgPool2d(output_size=(1, 1))
)
WARNING:trainer:Warning: visualization (Tensorboard) is configured to use, but currently not installed on this machine. Please ins
tall TensorboardX with 'pip install tensorboardx', upgrade PyTorch to version >= 1.1 to use 'torch.utils.tensorboard' or turn off
the option in the 'config.json' file.
Traceback (most recent call last):
  File "/home/nir/particles_repo/./train.py", line 100, in <module>
    main(config)
  File "/home/nir/particles_repo/./train.py", line 71, in main
    trainer.train()
  File "/home/nir/particles_repo/base/base_trainer.py", line 64, in train
    result = self._train_epoch(epoch)
  File "/home/nir/particles_repo/trainer/trainer.py", line 50, in _train_epoch
    for batch_idx, data in enumerate(self.data_loader):
  File "/home/nir/.local/lib/python3.10/site-packages/torch/utils/data/dataloader.py", line 681, in __next__
    data = self._next_data()
  File "/home/nir/.local/lib/python3.10/site-packages/torch/utils/data/dataloader.py", line 1376, in _next_data
    return self._process_data(data)
  File "/home/nir/.local/lib/python3.10/site-packages/torch/utils/data/dataloader.py", line 1402, in _process_data
    data.reraise()
  File "/home/nir/.local/lib/python3.10/site-packages/torch/_utils.py", line 461, in reraise
    raise exception
AttributeError: Caught AttributeError in DataLoader worker process 0.
Original Traceback (most recent call last):
  File "/home/nir/.local/lib/python3.10/site-packages/torch/utils/data/_utils/worker.py", line 302, in _worker_loop
    data = fetcher.fetch(index)
  File "/home/nir/.local/lib/python3.10/site-packages/torch/utils/data/_utils/fetch.py", line 49, in fetch
    data = [self.dataset[idx] for idx in possibly_batched_index]
  File "/home/nir/.local/lib/python3.10/site-packages/torch/utils/data/_utils/fetch.py", line 49, in <listcomp>
    data = [self.dataset[idx] for idx in possibly_batched_index]
  File "/home/nir/.local/lib/python3.10/site-packages/torch/utils/data/dataset.py", line 290, in __getitem__
    return self.dataset[self.indices[idx]]
  File "/home/nir/.local/lib/python3.10/site-packages/torch/utils/data/dataset.py", line 235, in __getitem__
    return self.datasets[dataset_idx][sample_idx]
  File "/home/nir/.local/lib/python3.10/site-packages/torch/utils/data/dataset.py", line 290, in __getitem__
    return self.dataset[self.indices[idx]]
  File "/home/nir/.local/lib/python3.10/site-packages/torch/utils/data/dataset.py", line 235, in __getitem__
    return self.datasets[dataset_idx][sample_idx]
  File "/home/nir/particles_repo/data_loader/data_loaders.py", line 200, in __getitem__
    en_dep_noise[i,j,k] = self.en_dep_noise[key_noise][k,i,j]
AttributeError: 'Bin_energy_data' object has no attribute 'en_dep_noise'

















mkdir: cannot create directory ‘./saved/models/saved_models/run_0’: File exists
mv: cannot stat './csv_files/epoch_*': No such file or directory













